Workbook

Sheet Indice

Sheet Estimativas Antropométricas
E1: PESO IDEAL
A2: CB | B2: 20 | D2: ALTURA | E2: 1.6
A3: AJ | B3: 52
A4: Idade | B4: 68 | D4: HOMEM IMC 22 | E4: =(E2*E2)*22 -> 56.32
A5: CP | B5: 29 | D5: MULHER IMC 20,8 | E5: =(E2*E2)*20.8 -> 53.248
A6: CC | B6: 30 | D6: IMC 25 | E6: =(E2*E2)*25 -> 64
A7: CA | B7: 80
A8: Gênero | B8: ALTURA ESTIMADA | C8: (Chumlea, 85)
A9: HOMEM | B9: =64.19-(0.04*B4)+(2.02*B3) -> 166.51 | D9: Peso Ajustado | E9: =(E10-E11)*0.33+E11 -> 78.97
A10: MULHER | B10: =84.88-(0.24*B4)+(1.83*B3) -> 163.72 | D10: Peso atual | E10: 85 | F10: insira o peso atual que vc quer utilizar
D11: Peso ideal | E11: 76 | F11: insira o peso ideal que vc quer utilizar
A12: Gênero | B12: PESO ESTIMADO | C12: (Chumlea, 88) | G12: %Adequação CB | L12: Classificação %CB
A13: HOMEM BRANCO 19-59 ANOS | B13: =(B3*1.19)+(B2*3.14)-86.82 -> 37.86 | G13: Percentil 50 CB | H13: P50 Homens | I13: P50 Mulheres | L13: Desn Grave | M13: <70%
A14: HOMEM BRANCO >60 ANOS | B14: =(B3*1.1)+(B2*3.07)-75.81 -> 42.79 | G14: 18-18,9 anos | H14: 30 | I14: 26.7 | L14: Desn Mod | M14: 70-80%
A15: HOMEM NEGRO 19-59 ANOS | B15: =(B3*1.09)+(B2*3.14)-83.72 -> 35.76 | G15: 19 - 19,9 anos | H15: 30.5 | I15: 26.8 | L15: Desn Leve | M15: 80-90%
A16: HOMEM NEGRO >60 ANOS | B16: =(B3*0.44)+(B2*2.86)-39.21 -> 40.87 | G16: 20- 29,9 anos | H16: 31.8 | I16: 28.1 | L16: Eutrofia | M16: 90-110%
A17: MULHER BRANCA 19-59 ANOS | B17: =(B3*1.01)+(B2*2.81)-66.04 -> 42.68 | G17: 30-39,9 anos | H17: 32.3 | I17: 30.3 | L17: Sobrepeso | M17: 110-120%
A18: MULHER BRANCA >60 ANOS | B18: =(B3*1.09)+(B2*2.68)-65.51 -> 44.77 | G18: 40-49,9 anos | H18: 33 | I18: 31.4 | L18: Obesidade | M18: >120%
A19: MULHER NEGRA 19-59 ANOS | B19: =(B3*1.24)+(B2*2.97)-82.48 -> 41.4 | G19: 50-59,9 anos | H19: 32.6 | I19: 31.9
A20: MULHER NEGRA >60 ANOS | B20: =(B3*1.5)+(B2*2.58)-84.22 -> 45.38 | G20: 60-69,9 anos | H20: 32 | I20: 31.4
G21: 70-79,9 anos | H21: 30.6 | I21: 29.9
G22: 80-90,9 anos | H22: 28.9 | I22: 27.8
B23: PESO ESTIMADO | C23: (Jung, 2004)
A24: HOMEM | B24: =(B3*0.928+B2*2.508-B4*0.144)-42.543 -> 46.081 | G24: CB medida | H24: 28
A25: MULHER | B25: =(B3*0.826+B2*2.116-B4*0.133)-31.486 -> 44.742 | G25: CB P50 | H25: 31.9
G26: % Adequação | H26: =H24/H25*100 -> 87.774295
B27: PESO ESTIMADO | C27: (Rabito, 2008)
A28: HOMEM | B28: =0.5759*B2+0.5263*B7+1.2452*B5-4.8689*1-32.9241 -> 51.9398
A29: MULHER | B29: =0.5759*B2+0.5263*B7+1.2452*B5-4.8689*2-32.9241 -> 47.0709 | G29: CP medida | H29: 29 | I29: (Barbosa-Silva, 2016)
G30: Homem: | H30: Se <34cm - indicativo de depleção muscular
G31: Mulher: | H31: Se <33cm - indicativo de depleção muscular
A32: % Perda de Peso (PP) | B32: =(B34-B33)*100/B34 -> 29.72973
A33: Peso atual | B33: 52
A34: Peso usual | B34: 74 | G34: Amputados | H34: % estimado | J34: Peso corrigido amputado | M34: =M35-((M35*M36)/100) -> 56.666
G35: Mão | H35: 0.7 | J35: Peso pré amputação | M35: 58
A36: Classificação PP | B36: Moderada | C36: Grave | G36: Antebraço | H36: 1.6 | J36: % do membro | M36: 2.3
A37: 1 SEMANA | B37: 1-2% | C37: ≥2% | G37: Antebraço + mão | H37: 2.3
A38: 1 MÊS | B38: <5% | C38: ≥5% | G38: Braço | H38: 2.7
A39: 3 MESES | B39: <7,5% | C39: ≥7,5% | G39: Membro superior | H39: 5
A40: 6 MESES | B40: <10% | C40: ≥10% | G40: Pé | H40: 1.5
...

Sheet Necessidades nutricionais
A1: Necessidades Nutricionais
B2: Fase aguda | C2: Reabilitação | E2: Peso | F2: 55
A3: Calorias | B3: 15 a 20 | C3: 25 a 30 | E3: Peso ideal | F3: 53
A4: (Minimo) | B4: =15*F2 -> 825 | C4: =25*F2 -> 1375 | F4: OU utilize a fórmula abaixo para necessidades personalizadas
A5: (Máximo) | B5: =20*F2 -> 1100 | C5: =30*F2 -> 1650 | F5: Kcal/kg | G5: 25 | H5: (necessidade desejada)
A6: Proteinas | B6: 1,2 a 1,5 | C6: >1,5 | F6: PTN/kg | G6: 1.8 | H6: (necessidade desejada)
A7: (Minimo) | B7: =1.2*F2 -> 66 | C7: =1.5*F2 -> 82.5
A8: (Máximo) | B8: =1.5*F2 -> 82.5 | C8: =2*F2 -> 110 | F8: KCAL TOTAL | G8: =G5*F2 -> 1375
A9: Se HD inter | B9: =F2*1.8 -> 99 | F9: PTN TOTAL | G9: =G6*F2 -> 99
A10: Se HD cont | B10: =2*F2 -> 110
A13: Obeso | B13: IMC>30 | C13: IMC>40
A14: Calorias | B14: 11-14kcal/PA | C14: 22-25kcal/PI
A15: Mínimo | B15: =11*F2 -> 605 | C15: =22*F3 -> 1166
A16: Máximo | B16: =14*F2 -> 770 | C16: =25*F3 -> 1325
A17: Proteinas | B17: =2*F3 -> 106 | C17: =2.5*F3 -> 132.5
B18: IMC>30 | C18: IMC >50

Sheet Cálculos dietas_Contínuo
A1: Dieta | B1: Densidade | C1: PTN | D1: Volume ml/h | E1: VT | F1: KCAL | G1: PTN | H1: kcal/kg | I1: ptn/kg | J1: % VCT | K1: % PTN | L1: VOLUME PLENO | M1: PTN PLENO | N1: PTN Suplementar | O1: Peso: | P1: 70 | R1: UTI = 22H
A2: Novasource Senior | B2: 1.24 | C2: 65 | E2: =D2*S2 -> 0 | F2: =B2*E2 -> 0 | G2: =C2*E2/1000 -> 0 | H2: =F2/P1 -> 0 | I2: =G2/P1 -> 0 | J2: =F2*100/P4 -> 0 | K2: =G2*100/P5 -> 0 | L2: =(P4/B2)/S2 -> 51.319648 | M2: =(L2*S2*C2)/1000 -> 73.387097 | N2: =P5-G2 -> 75 | O2: Altura: | P2: 1.8 | R2: nº horas | S2: 22
A3: Fresubin Original | B3: 1 | C3: 38 | D3: 69 | E3: =D3*S2 -> 1518 | F3: =B3*E3 -> 1518 | G3: =C3*E3/1000 -> 57.684 | H3: =F3/P1 -> 21.685714 | I3: =G3/P1 -> 0.82405714 | J3: =F3*100/P4 -> 108.42857 | K3: =G3*100/P5 -> 76.912 | L3: =(P4/B3)/S2 -> 63.636364 | M3: =(L3*S2*C3)/1000 -> 53.2 | N3: =P5-G3 -> 17.316
A4: Fresubin Original Fibre | B4: 1 | C4: 38 | E4: =D4*S2 -> 0 | F4: =B4*E4 -> 0 | G4: =C4*E4/1000 -> 0 | H4: =F4/P1 -> 0 | I4: =G4/P1 -> 0 | J4: =F4*100/P4 -> 0 | K4: =G4*100/P5 -> 0 | L4: =(P4/B4)/S2 -> 63.636364 | M4: =(L4*S2*C4)/1000 -> 53.2 | N4: =P5-G4 -> 75 | O4: VCT: | P4: 1400
A5: Fresubin Soya Fibre | B5: 1 | C5: 38 | E5: =D5*S2 -> 0 | F5: =B5*E5 -> 0 | G5: =C5*E5/1000 -> 0 | H5: =F5/P4 -> 0 | I5: =G5/P1 -> 0 | J5: =F5*100/P4 -> 0 | K5: =G5*100/P5 -> 0 | L5: =(P4/B5)/S2 -> 63.636364 | M5: =(L5*S2*C5)/1000 -> 53.2 | N5: =P5-G5 -> 75 | O5: PTN: | P5: 75
A6: Fresubin 1.2 HP Fibre | B6: 1.2 | C6: 60 | E6: =D6*S2 -> 0 | F6: =B6*E6 -> 0 | G6: =C6*E6/1000 -> 0 | H6: =F6/P5 -> 0 | I6: =G6/P1 -> 0 | J6: =F6*100/P4 -> 0 | K6: =G6*100/P5 -> 0 | L6: =(P4/B6)/S2 -> 53.030303 | M6: =(L6*S2*C6)/1000 -> 70 | N6: =P5-G6 -> 75
A7: Nutrison 1.0 | B7: 1 | C7: 40 | D7: 69 | E7: =D7*S2 -> 1518 | F7: =B7*E7 -> 1518 | G7: =C7*E7/1000 -> 60.72 | H7: =F7/P1 -> 21.685714 | I7: =G7/P1 -> 0.86742857 | J7: =F7*100/P4 -> 108.42857 | K7: =G7*100/P5 -> 80.96 | L7: =(P4/B7)/S2 -> 63.636364 | M7: =(L7*S2*C7)/1000 -> 56 | N7: =P5-G7 -> 14.28
A8: Nutri enteral Soya | B8: 1.2 | C8: 48 | E8: =D8*S2 -> 0 | F8: =B8*E8 -> 0 | G8: =C8*E8/1000 -> 0 | H8: =F8/P1 -> 0 | I8: =G8/P1 -> 0 | J8: =F8*100/P4 -> 0 | K8: =G8*100/P5 -> 0 | L8: =(P4/B8)/S2 -> 53.030303 | M8: =(L8*S2*C8)/1000 -> 56 | N8: =P5-G8 -> 75 | R8: Modelo de progressão
A9: Nutrison Multifiber | B9: 1 | C9: 40 | E9: =D9*S2 -> 0 | F9: =B9*E9 -> 0 | G9: =C9*E9/1000 -> 0 | H9: =F9/P1 -> 0 | I9: =G9/P1 -> 0 | J9: =F9*100/P4 -> 0 | K9: =G9*100/P5 -> 0 | L9: =(P4/B9)/S2 -> 63.636364 | M9: =(L9*S2*C9)/1000 -> 56 | N9: =P5-G9 -> 75
A10: Nutri enteral Soya Fiber | B10: 1.2 | C10: 44 | E10: =D10*S2 -> 0 | F10: =B10*E10 -> 0 | G10: =C10*E10/1000 -> 0 | H10: =F10/P1 -> 0 | I10: =G10/P1 -> 0 | J10: =F10*100/P4 -> 0 | K10: =G10*100/P5 -> 0 | L10: =(P4/B10)/S2 -> 53.030303 | M10: =(L10*S2*C10)/1000 -> 51.333333 | N10: =P5-G10 -> 75 | R10: Kcal/d | S10: Volume (1,5kcal) | T10: Volume (1,2kcal) | V10: Volume (1,0kcal)
A11: Isosource Mix | B11: 1.23 | C11: 43 | E11: =D11*S2 -> 0 | F11: =B11*E11 -> 0 | G11: =C11*E11/1000 -> 0 | H11: =F11/P1 -> 0 | I11: =G11/P1 -> 0 | J11: =F11*100/P4 -> 0 | K11: =G11*100/P5 -> 0 | L11: =(P4/B11)/S2 -> 51.736881 | M11: =(L11*S2*C11)/1000 -> 48.943089 | N11: =P11-G11 -> 0 | Q11: 1º dia 25% | R11: =P4*25/100 -> 350 | S11: =R11/1.5/S2 -> 10.606061 | T11: =R11/1.2/S2 -> 13.257576 | V11: =R11/S2 -> 15.909091
A12: Isosource Soya | B12: 1.21 | C12: 44 | E12: =D12*S2 -> 0 | F12: =B12*E12 -> 0 | G12: =C12*E12/1000 -> 0 | H12: =F12/P1 -> 0 | I12: =G12/P1 -> 0 | J12: =F12*100/P4 -> 0 | K12: =G12*100/P5 -> 0 | L12: =(P4/B12)/S2 -> 52.592036 | M12: =(L12*S2*C12)/1000 -> 50.909091 | N12: =P5-G12 -> 75 | Q12: 2º dia 50% | R12: =P4*50/100 -> 700 | S12: =R12/1.5/S2 -> 21.212121 | T12: =R12/1.2/S2 -> 26.515152 | V12: =R12/S2 -> 31.818182
A13: Isosource Soya Fiber | B13: 1.24 | C13: 44 | E13: =D13*S2 -> 0 | F13: =B13*E13 -> 0 | G13: =C13*E13/1000 -> 0 | H13: =F13/P1 -> 0 | I13: =G13/P1 -> 0 | J13: =F13*100/P4 -> 0 | K13: =G13*100/P5 -> 0 | L13: =(P4/B13)/S2 -> 51.319648 | M13: =(L13*S2*C13)/1000 -> 49.677419 | N13: =P5-G13 -> 75 | Q13: 3º dia 75% | R13: =P4*75/100 -> 1050 | S13: =R13/1.5/S2 -> 31.818182 | T13: =R13/1.2/S2 -> 39.772727 | V13: =R13/S2 -> 47.727273
A14: Trophic Basic | B14: 1.2 | C14: 46 | E14: =D14*S2 -> 0 | F14: =B14*E14 -> 0 | G14: =C14*E14/1000 -> 0 | H14: =F14/P1 -> 0 | I14: =G14/P1 -> 0 | J14: =F14*100/P4 -> 0 | K14: =G14*100/P5 -> 0 | L14: =(P4/B14)/S2 -> 53.030303 | M14: =(L14*S2*C14)/1000 -> 53.666667 | N14: =P5-G14 -> 75 | Q14: 4º dia 100% | R14: =P4 -> 1400 | S14: =R14/1.5/S2 -> 42.424242 | T14: =R14/1.2/S2 -> 53.030303 | V14: =R14/S2 -> 63.636364
A15: Trophic Fiber | B15: 1.2 | C15: 45 | E15: =D15*S2 -> 0 | F15: =B15*E15 -> 0 | G15: =C15*E15/1000 -> 0 | H15: =F15/P1 -> 0 | I15: =G15/P1 -> 0 | J15: =F15*100/P4 -> 0 | K15: =G15*100/P5 -> 0 | L15: =(P4/B15)/S2 -> 53.030303 | M15: =(L15*S2*C15)/1000 -> 52.5 | N15: =P5-G15 -> 75
A16: Trophic Soya | B16: 1.2 | C16: 46 | E16: =D16*S2 -> 0 | F16: =B16*E16 -> 0 | G16: =C16*E16/1000 -> 0 | H16: =F16/P1 -> 0 | I16: =G16/P1 -> 0 | J16: =F16*100/P4 -> 0 | K16: =G16*100/P5 -> 0 | L16: =(P4/B16)/S2 -> 53.030303 | M16: =(L16*S2*C16)/1000 -> 53.666667 | N16: =P5-G16 -> 75
A17: Fresubin Energy Fibre | B17: 1.5 | C17: 56 | E17: =D17*S2 -> 0 | F17: =B17*E17 -> 0 | G17: =C17*E17/1000 -> 0 | H17: =F17/P1 -> 0 | I17: =G17/P1 -> 0 | J17: =F17*100/P4 -> 0 | K17: =G17*100/P5 -> 0 | L17: =(P4/B17)/S2 -> 42.424242 | M17: =(L17*S2*C17)/1000 -> 52.266667 | N17: =P5-G17 -> 75 | Q17: PTN SUPLEMENTAR (em g faltantes) | U17: 72 | V17: ** iniciar o módulo proteina a partir do 4º dia
A18: Fresubin HP Energy | B18: 1.5 | C18: 75 | D18: 46 | E18: =D18*S2 -> 1012 | F18: =B18*E18 -> 1518 | G18: =C18*E18/1000 -> 75.9 | H18: =F18/P1 -> 21.685714 | I18: =G18/P1 -> 1.0842857 | J18: =F18*100/P4 -> 108.42857 | K18: =G18*100/P5 -> 101.2 | L18: =(P4/B18)/S2 -> 42.424242 | M18: =(L18*S2*C18)/1000 -> 70 | N18: =P5-G18 -> -0.9 | Q18: Nutren Just Protein | S18: =U17*15/Suplementos!C31 -> 83.076923 | U18: =U17*4 -> 288 | V18: kcal
A19: Isosource 1.5 | B19: 1.5 | C19: 63 | D19: 46 | E19: =D19*S2 -> 1012 | F19: =B19*E19 -> 1518 | G19: =C19*E19/1000 -> 63.756 | H19: =F19/P1 -> 21.685714 | I19: =G19/P1 -> 0.9108 | J19: =F19*100/P4 -> 108.42857 | K19: =G19*100/P5 -> 85.008 | L19: =(P4/B19)/S2 -> 42.424242 | M19: =(L19*S2*C19)/1000 -> 58.8 | N19: =P5-G19 -> 11.244 | Q19: Fresubin Protein Powder | S19: =U17*12/Suplementos!C32 -> 83.076923 | U19: =U17*4 -> 288 | V19: kcal
A20: Novasource Hi Protein | B20: 1.5 | C20: 83 | E20: =D20*S2 -> 0 | F20: =B20*E20 -> 0 | G20: =C20*E20/1000 -> 0 | H20: =F20/P1 -> 0 | I20: =G20/P1 -> 0 | J20: =F20*100/P4 -> 0 | K20: =G20*100/P5 -> 0 | L20: =(P4/B20)/S2 -> 42.424242 | M20: =(L20*S2*C20)/1000 -> 77.466667 | N20: =P5-G20 -> 75 | Q20: Nutridrink Protein | S20: =U17*20/Suplementos!C33 -> 240 | U20: =U17*4+(S20*9.66/20) -> 403.92 | V20: kcal
A21: Nutrison Energy | B21: 1.5 | C21: 60 | E21: =D21*S2 -> 0 | F21: =B21*E21 -> 0 | G21: =C21*E21/1000 -> 0 | H21: =F21/P1 -> 0 | I21: =G21/P1 -> 0 | J21: =F21*100/P4 -> 0 | K21: =G21*100/P5 -> 0 | L21: =(P4/B21)/S2 -> 42.424242 | M21: =(L21*S2*C21)/1000 -> 56 | N21: =P5-G21 -> 75
A22: Nutrison Energy Multifiber | B22: 1.5 | C22: 60 | E22: =D22*S2 -> 0 | F22: =B22*E22 -> 0 | G22: =C22*E22/1000 -> 0 | H22: =F22/P1 -> 0 | I22: =G22/P1 -> 0 | J22: =F22*100/P4 -> 0 | K22: =G22*100/P5 -> 0 | L22: =(P4/B22)/S2 -> 42.424242 | M22: =(L22*S2*C22)/1000 -> 56 | N22: =P5-G22 -> 75
A23: Nutri Enteral 1.5 | B23: 1.5 | C23: 64 | E23: =D23*S2 -> 0 | F23: =B23*E23 -> 0 | G23: =C23*E23/1000 -> 0 | H23: =F23/P1 -> 0 | I23: =G23/P1 -> 0 | J23: =F23*100/P4 -> 0 | K23: =G23*100/P5 -> 0 | L23: =(P4/B23)/S2 -> 42.424242 | M23: =(L23*S2*C23)/1000 -> 59.733333 | N23: =P5-G23 -> 75
A24: Isosource 1.5 | B24: 1.5 | C24: 63 | D24: 46 | E24: =D24*S2 -> 1012 | F24: =B24*E24 -> 1518 | G24: =C24*E24/1000 -> 63.756 | H24: =F24/P1 -> 21.685714 | I24: =G24/P1 -> 0.9108 | J24: =F24*100/P4 -> 108.42857 | K24: =G24*100/P5 -> 85.008 | L24: =(P4/B24)/S2 -> 42.424242 | M24: =(L24*S2*C24)/1000 -> 58.8 | N24: =P5-G24 -> 11.244
A25: Trophic 1.5 | B25: 1.5 | C25: 58 | E25: =D25*S2 -> 0 | F25: =B25*E25 -> 0 | G25: =C25*E25/1000 -> 0 | H25: =F25/P1 -> 0 | I25: =G25/P1 -> 0 | J25: =F25*100/P4 -> 0 | K25: =G25*100/P5 -> 0 | L25: =(P4/B25)/S2 -> 42.424242 | M25: =(L25*S2*C25)/1000 -> 54.133333 | N25: =P5-G25 -> 75
A26: Trophic EP | B26: 1.5 | C26: 69 | E26: =D26*S2 -> 0 | F26: =B26*E26 -> 0 | G26: =C26*E26/1000 -> 0 | H26: =F26/P1 -> 0 | I26: =G26/P1 -> 0 | J26: =F26*100/P4 -> 0 | K26: =G26*100/P5 -> 0 | L26: =(P4/B26)/S2 -> 42.424242 | M26: =(L26*S2*C26)/1000 -> 64.4 | N26: =P5-G26 -> 75
A27: Trophic 1.5 Soya | B27: 1.5 | C27: 57 | E27: =D27*S2 -> 0 | F27: =B27*E27 -> 0 | G27: =C27*E27/1000 -> 0 | H27: =F27/P1 -> 0 | I27: =G27/P1 -> 0 | J27: =F27*100/P4 -> 0 | K27: =G27*100/P5 -> 0 | L27: =(P4/B27)/S2 -> 42.424242 | M27: =(L27*S2*C27)/1000 -> 53.2 | N27: =P5-G27 -> 75
A28: Fresubin 2kcal HP (500ml) | B28: 2 | C28: 50 | D28: 34 | E28: =D28*S2 -> 748 | F28: =B28*E28 -> 1496 | G28: =C28*E28/500 -> 74.8 | H28: =F28/P1 -> 21.371429 | I28: =G28/P1 -> 1.0685714 | J28: =F28*100/P4 -> 106.85714 | K28: =G28*100/P5 -> 99.733333 | L28: =(P4/B28)/S2 -> 31.818182 | M28: =(L28*S2*C28)/1000 -> 35 | N28: =P5-G28 -> 0.2
A29: Fresubin 2kcal HP Fibre(500ml) | B29: 2 | C29: 50 | E29: =D29*S2 -> 0 | F29: =B29*E29 -> 0 | G29: =C29*E29/500 -> 0 | H29: =F29/P1 -> 0 | I29: =G29/P1 -> 0 | J29: =F29*100/P4 -> 0 | K29: =G29*100/P5 -> 0 | L29: =(P4/B29)/S2 -> 31.818182 | M29: =(L29*S2*C29)/1000 -> 35 | N29: =P5-G29 -> 75
A30: Diben | B30: 1 | C30: 46.5 | E30: =D30*S2 -> 0 | F30: =B30*E30 -> 0 | G30: =C30*E30/1000 -> 0 | H30: =F30/P1 -> 0 | I30: =G30/P1 -> 0 | J30: =F30*100/P4 -> 0 | K30: =G30*100/P5 -> 0 | L30: =(P4/B30)/S2 -> 63.636364 | M30: =(L30*S2*C30)/1000 -> 65.1 | N30: =P5-G30 -> 75
A31: Diben HP | B31: 1 | C31: 75 | E31: =D31*S2 -> 0 | F31: =B31*E31 -> 0 | G31: =C31*E31/1000 -> 0 | H31: =F31/P1 -> 0 | I31: =G31/P1 -> 0 | J31: =F31*100/P4 -> 0 | K31: =G31*100/P5 -> 0 | L31: =(P4/B31)/S2 -> 63.636364 | M31: =(L31*S2*C31)/1000 -> 105 | N31: =P5-G31 -> 75
A32: Novasource GC | B32: 1.12 | C32: 49 | E32: =D32*S2 -> 0 | F32: =B32*E32 -> 0 | G32: =C32*E32/1000 -> 0 | H32: =F32/P1 -> 0 | I32: =G32/P1 -> 0 | J32: =F32*100/P4 -> 0 | K32: =G32*100/P5 -> 0 | L32: =(P4/B32)/S2 -> 56.818182 | M32: =(L32*S2*C32)/1000 -> 61.25 | N32: =P5-G32 -> 75
A33: Novasource GC HP | B33: 1.14 | C33: 64 | E33: =D33*S2 -> 0 | F33: =B33*E33 -> 0 | G33: =C33*E33/1000 -> 0 | H33: =F33/P1 -> 0 | I33: =G33/P1 -> 0 | J33: =F33*100/P4 -> 0 | K33: =G33*100/P5 -> 0 | L33: =(P4/B33)/S2 -> 55.821372 | M33: =(L33*S2*C33)/1000 -> 78.596491 | N33: =P5-G33 -> 75
A34: Novasource GC 1.5 | B34: 1.5 | C34: 75 | E34: =D34*S2 -> 0 | F34: =B34*E34 -> 0 | G34: =C34*E34/1000 -> 0 | H34: =F34/P1 -> 0 | I34: =G34/P1 -> 0 | J34: =F34*100/P4 -> 0 | K34: =G34*100/P5 -> 0 | L34: =(P4/B34)/S2 -> 42.424242 | M34: =(L34*S2*C34)/1000 -> 70 | N34: =P5-G34 -> 75
A35: Diamax | B35: 1 | C35: 43 | E35: =D35*S2 -> 0 | F35: =B35*E35 -> 0 | G35: =C35*E35/1000 -> 0 | H35: =F35/P1 -> 0 | I35: =G35/P1 -> 0 | J35: =F35*100/P4 -> 0 | K35: =G35*100/P5 -> 0 | L35: =(P4/B35)/S2 -> 63.636364 | M35: =(L35*S2*C35)/1000 -> 60.2 | N35: =P5-G35 -> 75
A36: Novasource Ren | B36: 2 | C36: 74 | E36: =D36*S2 -> 0 | F36: =B36*E36 -> 0 | G36: =C36*E36/1000 -> 0 | H36: =F36/P1 -> 0 | I36: =G36/P1 -> 0 | J36: =F36*100/P4 -> 0 | K36: =G36*100/P5 -> 0 | L36: =(P4/B36)/S2 -> 31.818182 | M36: =(L36*S2*C36)/1000 -> 51.8 | N36: =P5-G36 -> 75
A37: Novasource GI control | B37: 1.5 | C37: 60 | E37: =D37*S2 -> 0 | F37: =B37*E37 -> 0 | G37: =C37*E37/1000 -> 0 | H37: =F37/P1 -> 0 | I37: =G37/P1 -> 0 | J37: =F37*100/P4 -> 0 | K37: =G37*100/P5 -> 0 | L37: =(P4/B37)/S2 -> 42.424242 | M37: =(L37*S2*C37)/1000 -> 56 | N37: =P5-G37 -> 75
A38: Novasource Proline | B38: 1 | C38: 58 | E38: =D38*S2 -> 0 | F38: =B38*E38 -> 0 | G38: =C38*E38/1000 -> 0 | H38: =F38/P1 -> 0 | I38: =G38/P1 -> 0 | J38: =F38*100/P4 -> 0 | K38: =G38*100/P5 -> 0 | L38: =(P4/B38)/S2 -> 63.636364 | M38: =(L38*S2*C38)/1000 -> 81.2 | N38: =P5-G38 -> 75
A39: Reconvan | B39: 1 | C39: 55 | E39: =D39*S2 -> 0 | F39: =B39*E39 -> 0 | G39: =C39*E39/1000 -> 0 | H39: =F39/P1 -> 0 | I39: =G39/P1 -> 0 | J39: =F39*100/P4 -> 0 | K39: =G39*100/P5 -> 0 | L39: =(P4/B39)/S2 -> 63.636364 | M39: =(L39*S2*C39)/1000 -> 77 | N39: =P5-G39 -> 75
A40: Fresubin Hepa | B40: 1.3 | C40: 40 | E40: =D40*S2 -> 0 | F40: =B40*E40 -> 0 | G40: =C40*E40/1000 -> 0 | H40: =F40/P1 -> 0 | I40: =G40/P1 -> 0 | J40: =F40*100/P4 -> 0 | K40: =G40*100/P5 -> 0 | L40: =(P4/B40)/S2 -> 48.951049 | M40: =(L40*S2*C40)/1000 -> 43.076923 | N40: =P5-G40 -> 75
...

Sheet Cálculos dietas_Intermitente
A1: Dieta | B1: Densidade | C1: PTN | D1: Volume do horário | E1: VT | F1: KCAL | G1: PTN | H1: kcal/kg | I1: ptn/kg | J1: % VCT | K1: % PTN | L1: VOLUME PLENO | M1: PTN PLENO | N1: PTN Suplementar | O1: Peso: | P1: 68 | R1: UTI = 22H
A2: Novasource Senior | B2: 1.24 | C2: 65 | D2: 133 | E2: =D2*S2 -> 798 | F2: =B2*E2 -> 989.52 | G2: =C2*E2/1000 -> 51.87 | H2: =F2/P1 -> 14.551765 | I2: =G2/P1 -> 0.76279412 | J2: =F2*100/P4 -> 74.963636 | K2: =G2*100/P5 -> 65.492424 | L2: =(P4/B2)/S2 -> 177.41935 | M2: =(L2*S2*C2)/1000 -> 69.193548 | N2: =P5-G2 -> 27.33 | O2: Altura: | P2: 1.62 | R2: nº vezes | S2: 6
A3: Fresubin Original | B3: 1 | C3: 38 | E3: =D3*S2 -> 0 | F3: =B3*E3 -> 0 | G3: =C3*E3/1000 -> 0 | H3: =F3/P1 -> 0 | I3: =G3/P1 -> 0 | J3: =F3*100/P4 -> 0 | K3: =G3*100/P5 -> 0 | L3: =(P4/B3)/S2 -> 220 | M3: =(L3*S2*C3)/1000 -> 50.16 | N3: =P5-G3 -> 79.2
A4: Fresubin Original Fibre | B4: 1 | C4: 38 | E4: =D4*S2 -> 0 | F4: =B4*E4 -> 0 | G4: =C4*E4/1000 -> 0 | H4: =F4/P1 -> 0 | I4: =G4/P1 -> 0 | J4: =F4*100/P4 -> 0 | K4: =G4*100/P5 -> 0 | L4: =(P4/B4)/S2 -> 220 | M4: =(L4*S2*C4)/1000 -> 50.16 | N4: =P5-G4 -> 79.2 | O4: VCT: | P4: 1320
A5: Fresubin Soya Fibre | B5: 1 | C5: 38 | E5: =D5*S2 -> 0 | F5: =B5*E5 -> 0 | G5: =C5*E5/1000 -> 0 | H5: =F5/P4 -> 0 | I5: =G5/P1 -> 0 | J5: =F5*100/P4 -> 0 | K5: =G5*100/P5 -> 0 | L5: =(P4/B5)/S2 -> 220 | M5: =(L5*S2*C5)/1000 -> 50.16 | N5: =P5-G5 -> 79.2 | O5: PTN: | P5: 79.2
A6: Fresubin 1.2 HP Fibre | B6: 1.2 | C6: 60 | E6: =D6*S2 -> 0 | F6: =B6*E6 -> 0 | G6: =C6*E6/1000 -> 0 | H6: =F6/P5 -> 0 | I6: =G6/P1 -> 0 | J6: =F6*100/P4 -> 0 | K6: =G6*100/P5 -> 0 | L6: =(P4/B6)/S2 -> 183.33333 | M6: =(L6*S2*C6)/1000 -> 66 | N6: =P5-G6 -> 79.2
A7: Nutrison 1.0 | B7: 1 | C7: 40 | E7: =D7*S2 -> 0 | F7: =B7*E7 -> 0 | G7: =C7*E7/1000 -> 0 | H7: =F7/P1 -> 0 | I7: =G7/P1 -> 0 | J7: =F7*100/P4 -> 0 | K7: =G7*100/P5 -> 0 | L7: =(P4/B7)/S2 -> 220 | M7: =(L7*S2*C7)/1000 -> 52.8 | N7: =P5-G7 -> 79.2
A8: Nutri enteral Soya | B8: 1.2 | C8: 48 | E8: =D8*S2 -> 0 | F8: =B8*E8 -> 0 | G8: =C8*E8/1000 -> 0 | H8: =F8/P1 -> 0 | I8: =G8/P1 -> 0 | J8: =F8*100/P4 -> 0 | K8: =G8*100/P5 -> 0 | L8: =(P4/B8)/S2 -> 183.33333 | M8: =(L8*S2*C8)/1000 -> 52.8 | N8: =P5-G8 -> 79.2 | R8: Modelo de progressão (volume de cada horário)
A9: Nutrison Multifiber | B9: 1 | C9: 40 | E9: =D9*S2 -> 0 | F9: =B9*E9 -> 0 | G9: =C9*E9/1000 -> 0 | H9: =F9/P1 -> 0 | I9: =G9/P1 -> 0 | J9: =F9*100/P4 -> 0 | K9: =G9*100/P5 -> 0 | L9: =(P4/B9)/S2 -> 220 | M9: =(L9*S2*C9)/1000 -> 52.8 | N9: =P5-G9 -> 79.2
A10: Nutri enteral Soya Fiber | B10: 1.2 | C10: 44 | E10: =D10*S2 -> 0 | F10: =B10*E10 -> 0 | G10: =C10*E10/1000 -> 0 | H10: =F10/P1 -> 0 | I10: =G10/P1 -> 0 | J10: =F10*100/P4 -> 0 | K10: =G10*100/P5 -> 0 | L10: =(P4/B10)/S2 -> 183.33333 | M10: =(L10*S2*C10)/1000 -> 48.4 | N10: =P5-G10 -> 79.2 | R10: Kcal/d | S10: Volume (1,5kcal) | T10: Volume (1,2kcal) | V10: Volume (1,0kcal)
A11: Isosource Mix | B11: 1.23 | C11: 43 | E11: =D11*S2 -> 0 | F11: =B11*E11 -> 0 | G11: =C11*E11/1000 -> 0 | H11: =F11/P1 -> 0 | I11: =G11/P1 -> 0 | J11: =F11*100/P4 -> 0 | K11: =G11*100/P5 -> 0 | L11: =(P4/B11)/S2 -> 178.86179 | M11: =(L11*S2*C11)/1000 -> 46.146341 | N11: =P11-G11 -> 0 | Q11: 1º dia 25% | R11: =P4*25/100 -> 330 | S11: =R11/1.5/S2 -> 36.666667 | T11: =R11/1.2/S2 -> 45.833333 | V11: =R11/S2 -> 55
A12: Isosource Soya | B12: 1.21 | C12: 44 | E12: =D12*S2 -> 0 | F12: =B12*E12 -> 0 | G12: =C12*E12/1000 -> 0 | H12: =F12/P1 -> 0 | I12: =G12/P1 -> 0 | J12: =F12*100/P4 -> 0 | K12: =G12*100/P5 -> 0 | L12: =(P4/B12)/S2 -> 181.81818 | M12: =(L12*S2*C12)/1000 -> 48 | N12: =P5-G12 -> 79.2 | Q12: 2º dia 50% | R12: =P4*50/100 -> 660 | S12: =R12/1.5/S2 -> 73.333333 | T12: =R12/1.2/S2 -> 91.666667 | V12: =R12/S2 -> 110
A13: Isosource Soya Fiber | B13: 1.24 | C13: 44 | E13: =D13*S2 -> 0 | F13: =B13*E13 -> 0 | G13: =C13*E13/1000 -> 0 | H13: =F13/P1 -> 0 | I13: =G13/P1 -> 0 | J13: =F13*100/P4 -> 0 | K13: =G13*100/P5 -> 0 | L13: =(P4/B13)/S2 -> 177.41935 | M13: =(L13*S2*C13)/1000 -> 46.83871 | N13: =P5-G13 -> 79.2 | Q13: 3º dia 75% | R13: =P4*75/100 -> 990 | S13: =R13/1.5/S2 -> 110 | T13: =R13/1.2/S2 -> 137.5 | V13: =R13/S2 -> 165
A14: Trophic Basic | B14: 1.2 | C14: 46 | E14: =D14*S2 -> 0 | F14: =B14*E14 -> 0 | G14: =C14*E14/1000 -> 0 | H14: =F14/P1 -> 0 | I14: =G14/P1 -> 0 | J14: =F14*100/P4 -> 0 | K14: =G14*100/P5 -> 0 | L14: =(P4/B14)/S2 -> 183.33333 | M14: =(L14*S2*C14)/1000 -> 50.6 | N14: =P5-G14 -> 79.2 | Q14: 4º dia 100% | R14: =P4 -> 1320 | S14: =R14/1.5/S2 -> 146.66667 | T14: =R14/1.2/S2 -> 183.33333 | V14: =R14/S2 -> 220
A15: Trophic Fiber | B15: 1.2 | C15: 45 | E15: =D15*S2 -> 0 | F15: =B15*E15 -> 0 | G15: =C15*E15/1000 -> 0 | H15: =F15/P1 -> 0 | I15: =G15/P1 -> 0 | J15: =F15*100/P4 -> 0 | K15: =G15*100/P5 -> 0 | L15: =(P4/B15)/S2 -> 183.33333 | M15: =(L15*S2*C15)/1000 -> 49.5 | N15: =P5-G15 -> 79.2
A16: Trophic Soya | B16: 1.2 | C16: 46 | E16: =D16*S2 -> 0 | F16: =B16*E16 -> 0 | G16: =C16*E16/1000 -> 0 | H16: =F16/P1 -> 0 | I16: =G16/P1 -> 0 | J16: =F16*100/P4 -> 0 | K16: =G16*100/P5 -> 0 | L16: =(P4/B16)/S2 -> 183.33333 | M16: =(L16*S2*C16)/1000 -> 50.6 | N16: =P5-G16 -> 79.2
A17: Fresubin Energy Fibre | B17: 1.5 | C17: 56 | E17: =D17*S2 -> 0 | F17: =B17*E17 -> 0 | G17: =C17*E17/1000 -> 0 | H17: =F17/P1 -> 0 | I17: =G17/P1 -> 0 | J17: =F17*100/P4 -> 0 | K17: =G17*100/P5 -> 0 | L17: =(P4/B17)/S2 -> 146.66667 | M17: =(L17*S2*C17)/1000 -> 49.28 | N17: =P5-G17 -> 79.2 | Q17: PTN SUPLEMENTAR (em g faltantes) | U17: 26 | V17: ** iniciar o módulo proteina a partir do 4º dia
A18: Fresubin HP Energy | B18: 1.5 | C18: 75 | D18: 110 | E18: =D18*S2 -> 660 | F18: =B18*E18 -> 990 | G18: =C18*E18/1000 -> 49.5 | H18: =F18/P1 -> 14.558824 | I18: =G18/P1 -> 0.72794118 | J18: =F18*100/P4 -> 75 | K18: =G18*100/P5 -> 62.5 | L18: =(P4/B18)/S2 -> 146.66667 | M18: =(L18*S2*C18)/1000 -> 66 | N18: =P5-G18 -> 29.7 | Q18: Nutren Just Protein | S18: =U17*15/Suplementos!C31 -> 30 | U18: =U17*4 -> 104 | V18: kcal
A19: Isosource 1.5 | B19: 1.5 | C19: 63 | E19: =D19*S2 -> 0 | F19: =B19*E19 -> 0 | G19: =C19*E19/1000 -> 0 | H19: =F19/P1 -> 0 | I19: =G19/P1 -> 0 | J19: =F19*100/P4 -> 0 | K19: =G19*100/P5 -> 0 | L19: =(P4/B19)/S2 -> 146.66667 | M19: =(L19*S2*C19)/1000 -> 55.44 | N19: =P5-G19 -> 79.2 | Q19: Fresubin Protein Powder | S19: =U17*12/Suplementos!C32 -> 30 | U19: =U17*4 -> 104 | V19: kcal
A20: Novasource Hi Protein | B20: 1.5 | C20: 83 | E20: =D20*S2 -> 0 | F20: =B20*E20 -> 0 | G20: =C20*E20/1000 -> 0 | H20: =F20/P1 -> 0 | I20: =G20/P1 -> 0 | J20: =F20*100/P4 -> 0 | K20: =G20*100/P5 -> 0 | L20: =(P4/B20)/S2 -> 146.66667 | M20: =(L20*S2*C20)/1000 -> 73.04 | N20: =P5-G20 -> 79.2 | Q20: Nutridrink Protein | S20: =U17*20/Suplementos!C33 -> 86.666667 | U20: =U17*4+(S20*9.66/20) -> 145.86 | V20: kcal
A21: Nutrison Energy | B21: 1.5 | C21: 60 | E21: =D21*S2 -> 0 | F21: =B21*E21 -> 0 | G21: =C21*E21/1000 -> 0 | H21: =F21/P1 -> 0 | I21: =G21/P1 -> 0 | J21: =F21*100/P4 -> 0 | K21: =G21*100/P5 -> 0 | L21: =(P4/B21)/S2 -> 146.66667 | M21: =(L21*S2*C21)/1000 -> 52.8 | N21: =P5-G21 -> 79.2
A22: Nutrison Energy Multifiber | B22: 1.5 | C22: 60 | E22: =D22*S2 -> 0 | F22: =B22*E22 -> 0 | G22: =C22*E22/1000 -> 0 | H22: =F22/P1 -> 0 | I22: =G22/P1 -> 0 | J22: =F22*100/P4 -> 0 | K22: =G22*100/P5 -> 0 | L22: =(P4/B22)/S2 -> 146.66667 | M22: =(L22*S2*C22)/1000 -> 52.8 | N22: =P5-G22 -> 79.2
A23: Nutri Enteral 1.5 | B23: 1.5 | C23: 64 | E23: =D23*S2 -> 0 | F23: =B23*E23 -> 0 | G23: =C23*E23/1000 -> 0 | H23: =F23/P1 -> 0 | I23: =G23/P1 -> 0 | J23: =F23*100/P4 -> 0 | K23: =G23*100/P5 -> 0 | L23: =(P4/B23)/S2 -> 146.66667 | M23: =(L23*S2*C23)/1000 -> 56.32 | N23: =P5-G23 -> 79.2
A24: Isosource 1.5 | B24: 1.5 | C24: 63 | E24: =D24*S2 -> 0 | F24: =B24*E24 -> 0 | G24: =C24*E24/1000 -> 0 | H24: =F24/P1 -> 0 | I24: =G24/P1 -> 0 | J24: =F24*100/P4 -> 0 | K24: =G24*100/P5 -> 0 | L24: =(P4/B24)/S2 -> 146.66667 | M24: =(L24*S2*C24)/1000 -> 55.44 | N24: =P5-G24 -> 79.2
A25: Trophic 1.5 | B25: 1.5 | C25: 58 | E25: =D25*S2 -> 0 | F25: =B25*E25 -> 0 | G25: =C25*E25/1000 -> 0 | H25: =F25/P1 -> 0 | I25: =G25/P1 -> 0 | J25: =F25*100/P4 -> 0 | K25: =G25*100/P5 -> 0 | L25: =(P4/B25)/S2 -> 146.66667 | M25: =(L25*S2*C25)/1000 -> 51.04 | N25: =P5-G25 -> 79.2
A26: Trophic EP | B26: 1.5 | C26: 69 | E26: =D26*S2 -> 0 | F26: =B26*E26 -> 0 | G26: =C26*E26/1000 -> 0 | H26: =F26/P1 -> 0 | I26: =G26/P1 -> 0 | J26: =F26*100/P4 -> 0 | K26: =G26*100/P5 -> 0 | L26: =(P4/B26)/S2 -> 146.66667 | M26: =(L26*S2*C26)/1000 -> 60.72 | N26: =P5-G26 -> 79.2
A27: Trophic 1.5 Soya | B27: 1.5 | C27: 57 | E27: =D27*S2 -> 0 | F27: =B27*E27 -> 0 | G27: =C27*E27/1000 -> 0 | H27: =F27/P1 -> 0 | I27: =G27/P1 -> 0 | J27: =F27*100/P4 -> 0 | K27: =G27*100/P5 -> 0 | L27: =(P4/B27)/S2 -> 146.66667 | M27: =(L27*S2*C27)/1000 -> 50.16 | N27: =P5-G27 -> 79.2
A28: Fresubin 2kcal HP (500ml) | B28: 2 | C28: 50 | E28: =D28*S2 -> 0 | F28: =B28*E28 -> 0 | G28: =C28*E28/500 -> 0 | H28: =F28/P1 -> 0 | I28: =G28/P1 -> 0 | J28: =F28*100/P4 -> 0 | K28: =G28*100/P5 -> 0 | L28: =(P4/B28)/S2 -> 110 | M28: =(L28*S2*C28)/1000 -> 33 | N28: =P5-G28 -> 79.2
A29: Fresubin 2kcal HP Fibre(500ml) | B29: 2 | C29: 50 | E29: =D29*S2 -> 0 | F29: =B29*E29 -> 0 | G29: =C29*E29/500 -> 0 | H29: =F29/P1 -> 0 | I29: =G29/P1 -> 0 | J29: =F29*100/P4 -> 0 | K29: =G29*100/P5 -> 0 | L29: =(P4/B29)/S2 -> 110 | M29: =(L29*S2*C29)/1000 -> 33 | N29: =P5-G29 -> 79.2
A30: Diben | B30: 1 | C30: 46.5 | E30: =D30*S2 -> 0 | F30: =B30*E30 -> 0 | G30: =C30*E30/1000 -> 0 | H30: =F30/P1 -> 0 | I30: =G30/P1 -> 0 | J30: =F30*100/P4 -> 0 | K30: =G30*100/P5 -> 0 | L30: =(P4/B30)/S2 -> 220 | M30: =(L30*S2*C30)/1000 -> 61.38 | N30: =P5-G30 -> 79.2
A31: Diben HP | B31: 1 | C31: 75 | E31: =D31*S2 -> 0 | F31: =B31*E31 -> 0 | G31: =C31*E31/1000 -> 0 | H31: =F31/P1 -> 0 | I31: =G31/P1 -> 0 | J31: =F31*100/P4 -> 0 | K31: =G31*100/P5 -> 0 | L31: =(P4/B31)/S2 -> 220 | M31: =(L31*S2*C31)/1000 -> 99 | N31: =P5-G31 -> 79.2
A32: Novasource GC | B32: 1.12 | C32: 49 | E32: =D32*S2 -> 0 | F32: =B32*E32 -> 0 | G32: =C32*E32/1000 -> 0 | H32: =F32/P1 -> 0 | I32: =G32/P1 -> 0 | J32: =F32*100/P4 -> 0 | K32: =G32*100/P5 -> 0 | L32: =(P4/B32)/S2 -> 196.42857 | M32: =(L32*S2*C32)/1000 -> 57.75 | N32: =P5-G32 -> 79.2
A33: Novasource GC HP | B33: 1.14 | C33: 64 | E33: =D33*S2 -> 0 | F33: =B33*E33 -> 0 | G33: =C33*E33/1000 -> 0 | H33: =F33/P1 -> 0 | I33: =G33/P1 -> 0 | J33: =F33*100/P4 -> 0 | K33: =G33*100/P5 -> 0 | L33: =(P4/B33)/S2 -> 192.98246 | M33: =(L33*S2*C33)/1000 -> 74.105263 | N33: =P5-G33 -> 79.2
A34: Novasource GC 1.5 | B34: 1.5 | C34: 75 | E34: =D34*S2 -> 0 | F34: =B34*E34 -> 0 | G34: =C34*E34/1000 -> 0 | H34: =F34/P1 -> 0 | I34: =G34/P1 -> 0 | J34: =F34*100/P4 -> 0 | K34: =G34*100/P5 -> 0 | L34: =(P4/B34)/S2 -> 146.66667 | M34: =(L34*S2*C34)/1000 -> 66 | N34: =P5-G34 -> 79.2
A35: Diamax | B35: 1 | C35: 43 | E35: =D35*S2 -> 0 | F35: =B35*E35 -> 0 | G35: =C35*E35/1000 -> 0 | H35: =F35/P1 -> 0 | I35: =G35/P1 -> 0 | J35: =F35*100/P4 -> 0 | K35: =G35*100/P5 -> 0 | L35: =(P4/B35)/S2 -> 220 | M35: =(L35*S2*C35)/1000 -> 56.76 | N35: =P5-G35 -> 79.2
A36: Novasource Ren | B36: 2 | C36: 74 | E36: =D36*S2 -> 0 | F36: =B36*E36 -> 0 | G36: =C36*E36/1000 -> 0 | H36: =F36/P1 -> 0 | I36: =G36/P1 -> 0 | J36: =F36*100/P4 -> 0 | K36: =G36*100/P5 -> 0 | L36: =(P4/B36)/S2 -> 110 | M36: =(L36*S2*C36)/1000 -> 48.84 | N36: =P5-G36 -> 79.2
A37: Novasource GI control | B37: 1.5 | C37: 60 | E37: =D37*S2 -> 0 | F37: =B37*E37 -> 0 | G37: =C37*E37/1000 -> 0 | H37: =F37/P1 -> 0 | I37: =G37/P1 -> 0 | J37: =F37*100/P4 -> 0 | K37: =G37*100/P5 -> 0 | L37: =(P4/B37)/S2 -> 146.66667 | M37: =(L37*S2*C37)/1000 -> 52.8 | N37: =P5-G37 -> 79.2
A38: Novasource Proline | B38: 1 | C38: 58 | E38: =D38*S2 -> 0 | F38: =B38*E38 -> 0 | G38: =C38*E38/1000 -> 0 | H38: =F38/P1 -> 0 | I38: =G38/P1 -> 0 | J38: =F38*100/P4 -> 0 | K38: =G38*100/P5 -> 0 | L38: =(P4/B38)/S2 -> 220 | M38: =(L38*S2*C38)/1000 -> 76.56 | N38: =P5-G38 -> 79.2
A39: Reconvan | B39: 1 | C39: 55 | E39: =D39*S2 -> 0 | F39: =B39*E39 -> 0 | G39: =C39*E39/1000 -> 0 | H39: =F39/P1 -> 0 | I39: =G39/P1 -> 0 | J39: =F39*100/P4 -> 0 | K39: =G39*100/P5 -> 0 | L39: =(P4/B39)/S2 -> 220 | M39: =(L39*S2*C39)/1000 -> 72.6 | N39: =P5-G39 -> 79.2
A40: Fresubin Hepa | B40: 1.3 | C40: 40 | E40: =D40*S2 -> 0 | F40: =B40*E40 -> 0 | G40: =C40*E40/1000 -> 0 | H40: =F40/P1 -> 0 | I40: =G40/P1 -> 0 | J40: =F40*100/P4 -> 0 | K40: =G40*100/P5 -> 0 | L40: =(P4/B40)/S2 -> 169.23077 | M40: =(L40*S2*C40)/1000 -> 40.615385 | N40: =P5-G40 -> 79.2
...

Sheet TNE Sistema aberto
B1: kcal | C1: cho | D1: ptn | E1: lip
A2: Trophic basic pó (1 medida - 7,8g) | B2: 33.93 | C2: 4.68 | D2: 1.24 | E2: 1.09 | I2: VET | J2: 1200 | K2: 15% PTN | L2: 20% PTN
A3: Carbodex (1 medida - 10g) | B3: 40 | C3: 10 | D3: 0 | E3: 0 | I3: PTN | J3: 45 | K3: =(J2*15/100)/4 -> 45 | L3: =(J2*20/100)/4 -> 60
A4: Albumix power (1 medidor - 20g) | B4: 70 | C4: 1.5 | D4: 16 | E4: 0
A5: Oleo de soja (1 colher sopa 13ml) | B5: 108 | C5: 0 | D5: 0 | E5: 12 | I5: Peso | J5: 60
A8: Dieta | B8: dose | C8: CHO | D8: PTN | E8: LIP | F8: Kcal/kg | G8: Ptn/kg | H8: % CHO | I8: % PTN | J8: %LIP
A9: Trophic - nº doses | B9: =((J2-(E13*9))/B2)*85/100 -> 28.709107 | C9: =B9*C2 -> 134.35862 | D9: =B9*D2 -> 35.599293 | E9: =B9*E2 -> 31.292927 | F9: =B14/J5 -> 20.091133 | G9: =D12/J5 -> 0.85998821 | H9: =(C12*4)*100/J2 -> 55.286207 | I9: =(D12*4)*100/J2 -> 17.199764 | J9: =(E12*9)*100/J2 -> 27.969695
A10: Carbodex - nº doses | B10: 3 | C10: =B10*C3 -> 30
A11: Albumix - nº medidores | B11: 1 | C11: =B11*C4 -> 1.5 | D11: =B11*D4 -> 16 | E11: 0
B12: =(D12*4)+((C11+C9)*4)+E12*9 -> 1085.468 | C12: =C9+C11+C10 -> 165.85862 | D12: =D9+D11 -> 51.599293 | E12: =E9+E11+E13 -> 37.292927
A13: óleo 1 colher sopa | B13: 0.5 | E13: =B13*E5 -> 6
A14: Total em kcal | B14: =B12+B10*B3 -> 1205.468
A15: água | B15: =28.5*B9+100+(B10*100) -> 1218.2095
A16: 4 Doses de em ml | B16: =B15/4 -> 304.55239
A17: Lata Trophic | B17: =(B9*7.8/800)*31 -> 8.6773276
A18: Lata Cabodex | B18: =((B10*10)/500)*31 -> 1.86
A19: Lata Albumix | B19: =((B11*20)/500)*31 -> 1.24
A20: óleo de soja | B20: =(B13*10/900)*31 -> 0.17222222
A23: Receita para cada DOSE | B23: MEDIDORES
A24: Trophic | B24: =B9/4 -> 7.1772767 | C24: dosadores
A25: Carbodex | B25: =B10/4 -> 0.75 | C25: dosadores
A26: Albumix | B26: =B11/4 -> 0.25 | C26: g
A27: óleo | B27: =13/4 -> 3.25 | C27: ml

Sheet Hidratação
D2: HIDRATAÇÃO | G2: Peso | H2: 70
G3: Volume de dieta/dia | H3: 1500
D4: 25 a 30ml/Kg/dia
C5: Mínimo | D5: =H2*25 -> 1750 | G5: Dieta 2,0kcal | H5: 70
C6: Ideal | D6: =H2*30 -> 2100 | G6: Dieta 1,5kcal | H6: 75
G7: Dieta 1,2kcal | H7: 80
G8: Dieta 1,0kcal | H8: 85
C9: Água via TNE
C10: Dieta 2,0kcal | D10: =H3*H5/100 -> 1050
C11: Dieta 1,5kcal | D11: =H3*H6/100 -> 1125
C12: Dieta 1,2kcal | D12: =H3*H7/100 -> 1200
C13: Dieta 1,0kcal | D13: =H3*H8/100 -> 1275
C15: Oferta água extra TNE | E15: **dividir este volume mínimo ou ideal no nº de vezes que deseja ofertar
D16: Mínimo | E16: Ideal | F16: 4x/dia | G16: 5x/dia | H16: 6x/dia | I16: 8x
C17: Dieta 2,0kcal | D17: =D5-D10 -> 700 | E17: =D6-D10 -> 1050 | F17: =E17/4 -> 262.5 | G17: =E17/5 -> 210 | H17: =E17/6 -> 175 | I17: =E17/8 -> 131.25
C18: Dieta 1,5kcal | D18: =D5-D11 -> 625 | E18: =D6-D11 -> 975 | F18: =E18/4 -> 243.75 | G18: =E18/5 -> 195 | H18: =E18/6 -> 162.5 | I18: =E18/8 -> 121.875
C19: Dieta 1,2kcal | D19: =D5-D12 -> 550 | E19: =D6-D12 -> 900 | F19: =E19/4 -> 225 | G19: =E19/5 -> 180 | H19: =E19/6 -> 150 | I19: =E19/8 -> 112.5
C20: Dieta 1,0kcal | D20: =D5-D13 -> 475 | E20: =D6-D13 -> 825 | F20: =E20/4 -> 206.25 | G20: =E20/5 -> 165 | H20: =E20/6 -> 137.5 | I20: =E20/8 -> 103.125
C21: TNE S.A. | D21: =D5-Hidratação!B15 -> 1750 | E21: =D6-Hidratação!B15 -> 2100 | F21: =E21/4 -> 525 | G21: =E21/5 -> 420 | H21: =E21/6 -> 350 | I21: =E21/8 -> 262.5

Sheet Cálculos
B1: Calculo Noradrenalina | D1: *considerando diluição em 250ml soro | I1: Calculo Noradrenalina
A2: Noradrenalina | B2: Volume ml/h | C2: mcg/kg/min | J2: Volume ml/h
A3: simples | B3: 32 | C3: =B3*32/B6/60 -> 0.2625641 | D3: *considerando 2 ampolas de Nora | I3: mL de nora | J3: 15
A4: concentrada | B4: 35 | C4: =B4*64/B6/60 -> 0.57435897 | D4: *considerando 4 ampolas de Nora | I4: nº ampolas diluidas | J4: 2
I5: Quantidade de soro | J5: 100
A6: Peso(kg) | B6: 65 | I6: mcg/kg/min | J6: =J4*4/J5/60/B6*J3*1000 -> 0.30769231
B10: Balanço nitrogenado
A11: Ptn(g) ingerida 24h | B11: 95 | C11: =B11/6.25 -> 15.2
A12: Ureia urinária 24h | B12: 40 | C12: =B12/2.14+4 -> 22.691589
A13: Balanço total | B13: =C11-C12 -> -7.4915888
B16: Calorias Propofol
A17: Volume ml/h | B17: 15
A18: Calorias totais | B18: =B17*24*1.1 -> 396

Sheet Suplementos
A1: Suplemento | B1: QTD (g) | C1: KCAL | D1: PTN | E1: CHO | F1: AÇ | G1: LIP | H1: Sódio | I1: Potássio | J1: Fósforo | K1: Ferro | L1: Fibras | M1: Osmolaridade
A2: Diamax | B2: 200 | C2: 200 | D2: 8.8 | E2: 20 | F2: 0.4 | G2: 9.4 | H2: 134 | I2: 272 | J2: 142 | K2: 2.2 | L2: 3 | M2: NI | N2: *auxiliar no controle glicêmico
A3: Energyzip | B3: 200 | C3: 300 | D3: 12 | E3: 40 | F3: 13 | G3: 10.4 | H3: 298 | I3: 454 | J3: NI | K3: 2.6 | L3: 0 | M3: NI
A4: Fresubin 2kcal Neutro | B4: 200 | C4: 400 | D4: 20 | E4: 44 | F4: 7 | G4: 15.6 | H4: 120 | I4: 320 | J4: 240 | K4: 5 | L4: 0 | M4: 495 | N4: *presença de w3,w6
A5: Fresubin 3.2kcal | B5: 125 | C5: 400 | D5: 20 | E5: 35 | F5: NI | G5: 20 | H5: 140 | I5: 390 | J5: 140 | K5: 6 | L5: 0.62 | M5: NI
A6: Fresubin Energy | B6: 200 | C6: 300 | D6: 11.2 | E6: 38 | F6: 11 | G6: 11.6 | H6: 160 | I6: 270 | J6: 160 | K6: 4 | L6: 0 | M6: 390 | P6: NI= Não informado
A7: Fresubin Jucy | B7: 200 | C7: 300 | D7: 8 | E7: 67 | G7: 0 | H7: 12 | I7: 14 | M7: 680
A8: Fresubin Protein Energy | B8: 200 | C8: 300 | D8: 20 | E8: 24 | F8: 14.6 | G8: 13.4 | H8: 116 | I8: 292 | J8: 240 | K8: 5 | L8: 0 | M8: 440
A9: Glucerna 1.5 | B9: 200 | C9: 306 | D9: 15 | E9: 26 | F9: 12.2 | G9: 15 | H9: 240 | I9: 330 | J9: 200 | K9: 1.7 | L9: 3.4 | M9: 614
A10: Impact | B10: 200 | C10: 214 | D10: 13 | E10: 14 | F10: 0 | G10: 5.6 | H10: 120 | I10: 420 | J10: 170 | K10: 2.6 | L10: 0 | M10: 297 | N10: *presença de arginina, w3,w6, nucleotídeos
A11: Just Protein | B11: 20 | C11: 69.3 | D11: 17.33 | E11: 0
A12: Novasource Proline | B12: 200 | C12: 274 | D12: 20 | E12: 32 | F12: 3 | G12: 7.4 | H12: 200 | I12: 310 | J12: 190 | K12: 3.2 | L12: 1 | M12: NI | N12: *presença de arginina, w3,w6, prolina, colina
A13: Novasource Ren | B13: 200 | C13: 400 | D13: 14.8 | E13: 40 | F13: 11.8 | G13: 20 | H13: 280 | I13: 300 | J13: 190 | K13: 4 | L13: 0 | M13: 740 | N13: *presença de carnitina, arginina, w3,w6, taurina
A14: Novasource Senior pó s/sabor | B14: 27.5 | C14: 116.05 | D14: 9.9 | E14: 9.9 | F14: NI | G14: 4.12 | H14: 50 | I14: 137.5 | J14: 110 | K14: 1.95 | L14: 1.1 | M14: NI | N14: 3 Colheres sopa = 27,5g
A15: Novasourse Senior | B15: 200 | C15: 198 | D15: 16 | E15: 19 | F15: 1.2 | G15: 6.4 | H15: 154 | I15: NI | J15: NI | K15: NI | L15: 0 | M15: NI
A16: Nutren 1.5 | B16: 200 | C16: 308 | D16: 11.2 | E16: 44 | F16: 16 | G16: 9.6 | H16: 140 | I16: 160 | J16: 170 | K16: 4.4 | L16: 0 | M16: NI
A17: Nutren 1.5 Protein | B17: 200 | C17: 296 | D17: 20 | E17: 22 | F17: 17.8 | G17: 14.4 | H17: 224 | I17: 394 | J17: 288 | K17: 3.6 | L17: 0 | M17: NI
A18: Nutren 2.0 | B18: 200 | C18: 400 | D18: 17.2 | E18: 12 | F18: 12 | G18: 19.2 | H18: NI | I18: 460 | J18: 160 | K18: 6 | L18: 0 | M18: NI
A19: Nutren Control | B19: 200 | C19: 212 | D19: 15 | E19: 14.4 | F19: 4.6 | G19: 10 | H19: 144 | I19: NI | J19: 170 | K19: 2.8 | L19: 0 | N19: *auxiliar no controle glicêmico
A20: Nutren Forfity Pó | B20: 30 | C20: 132 | D20: 9 | E20: 11 | F20: 0.8 | G20: 5.6 | H20: 35 | I20: NI | J20: 111 | K20: 2.9 | L20: 0 | M20: NI | N20: (30g + 90ml água = 100ml preparação)
A21: Nutren Fresh Chá de limão | B21: 200 | C21: 272 | D21: 10 | E21: 58 | F21: 16.4 | G21: 0 | H21: 90 | I21: NI | J21: NI | K21: NI | L21: 0 | M21: NI
A22: Nutren Ultra | B22: 125 | C22: 278.7 | D22: 20 | E22: 18.7 | F22: 11.87 | G22: 13.75 | H22: 212.5 | I22: 277.5 | J22: 191.25 | K22: 1.87 | L22: 0 | M22: NI
A23: Nutri enteral 1.5 | B23: 200 | C23: 300 | D23: 12.8 | E23: 42 | F23: NI | G23: 8.4 | H23: 180 | I23: 340 | J23: 140 | K23: 2.8 | L23: 0 | M23: NI
A24: Nutridrink | B24: 200 | C24: 300 | D24: 18.4 | E24: 17 | F24: NI | G24: 10.4 | H24: 120 | I24: 416 | J24: 330 | K24: 3.2 | L24: 0 | M24: NI
A30: Módulos proteicos | B30: g | C30: ptn | D30: cho | E30: kcal
A31: Nutren Just Protein | B31: 15 | C31: 13 | D31: 0 | E31: =C31*4 -> 52
A32: Fresubin Protein Powder | B32: 12 | C32: 10.4 | D32: 0 | E32: =C32*4 -> 41.6
A33: Nutridrink Protein | B33: 20 | C33: 6 | D33: 9.66 | E33: 62.64

Sheet Dietas consulta
A1: Fórmula | B1: Densidade | C1: PTN | D1: CHO | E1: LIP | F1: Fibras | G1: K | H1: Osmol.
A2: Novasource Senior | B2: 1.24 | C2: 65 | D2: 140 | E2: 47 | F2: 0 | G2: 1950 | H2: 333
A3: Fresubin Original | B3: 1 | C3: 38 | D3: 138 | E3: 34 | F3: 0 | G3: 1250 | H3: 220
A4: Fresubin Original Fibre | B4: 1 | C4: 38 | D4: 130 | E4: 34 | F4: 13 | G4: 1550 | H4: 285
A5: Fresubin Soya Fibre | B5: 1 | C5: 38 | D5: 121 | E5: 36 | F5: 20 | G5: 1330 | H5: 410
A6: Fresubin 1.2 HP Fibre | B6: 1.2 | C6: 60 | D6: 140 | E6: 41 | F6: 20 | G6: 2230 | H6: 345
A7: Nutrison 1.0 | B7: 1 | C7: 40 | D7: 120 | E7: 39 | F7: 0 | G7: 1500 | H7: 255
A8: Nutri enteral Soya | B8: 1.2 | C8: 48 | D8: 170 | E8: 37 | F8: 0 | G8: 1700 | H8: 305
A9: Nutrison Multifiber | B9: 1 | C9: 40 | D9: 120 | E9: 39 | F9: 15 | G9: 1500 | H9: 255
A10: Nutri enteral Soya Fiber | B10: 1.2 | C10: 44 | D10: 170 | E10: 40 | F10: 18 | G10: 1330 | H10: 305
A11: Isosource Mix | B11: 1.23 | C11: 43 | D11: 160 | E11: 46 | F11: 15 | G11: 1700 | H11: 305
A12: Isosource Soya | B12: 1.21 | C12: 44 | D12: 170 | E12: 39 | F12: 0 | G12: 1900 | H12: 276
A13: Isosource Soya Fiber | B13: 1.24 | C13: 44 | D13: 170 | E13: 43 | F13: 17 | G13: 1950 | H13: 321
... A51: Nutrison Advanced Peptisorb | B51: 1 | C51: 40 | D51: 180 | E51: 170 | F51: 0 | G51: 1500 | H51: 455

Sheet Controle Ingestão
G2: Média 5 dias: | H2: =(B23+E23+H23+K23+N23)/5 -> 35
A15: DIA 1 | D15: DIA 2 | G15: DIA 3 | J15: DIA 4 | M15: DIA 5
A16: % de Consumo | D16: % de Consumo | G16: % de Consumo | J16: % de Consumo | M16: % de Consumo
A17: Café da manhã | B17: 25 | D17: Café da manhã | E17: 25 | G17: Café da manhã | H17: 25 | J17: Café da manhã | K17: 25 | M17: Café da manhã | N17: 25
A18: Lanche da manhã | B18: 50 | D18: Lanche da manhã | E18: 25 | G18: Lanche da manhã | H18: 25 | J18: Lanche da manhã | K18: 25 | M18: Lanche da manhã | N18: 25
A19: Almoço | B19: 75 | D19: Almoço | E19: 50 | G19: Almoço | H19: 50 | J19: Almoço | K19: 50 | M19: Almoço | N19: 50
A20: Lanche da tarde | B20: 25 | D20: Lanche da tarde | E20: 25 | G20: Lanche da tarde | H20: 25 | J20: Lanche da tarde | K20: 25 | M20: Lanche da tarde | N20: 25
A21: Jantar | B21: 50 | D21: Jantar | E21: 75 | G21: Jantar | H21: 75 | J21: Jantar | K21: 75 | M21: Jantar | N21: 75
A22: Ceia | B22: 25 | D22: Ceia | E22: 0 | G22: Ceia | H22: 0 | J22: Ceia | K22: 0 | M22: Ceia | N22: 0
A23: Média | B23: =AVERAGE(B17:B22) -> 41.666667 | D23: Média | E23: =AVERAGE(E17:E22) -> 33.333333 | G23: Média | H23: =AVERAGE(H17:H22) -> 33.333333 | J23: Média | K23: =AVERAGE(K17:K22) -> 33.333333 | M23: Média | N23: =AVERAGE(N17:N22) -> 33.333333

Sheet Prescr x Inf
A1: Prescrito x Infundido - TNE
A2: Paciente | B2: Identificação | C2: Vol. Recebido 24h | D2: Vol. Prescrito | E2: % Recebido
A3: João da Silva | B3: 15023 | C3: 995 | D3: 1150 | E3: =C3*100/D3 -> 86.521739
C4: 1100 | D4: 1350 | E4: =C4*100/D4 -> 81.481481
E5: =C5*100/D5 -> #DIV/0!
C6: 990 | D6: 1110 | E6: =C6*100/D6 -> 89.189189
E7: =C7*100/D7 -> #DIV/0!
E8: =C8*100/D8 -> #DIV/0!
E9: =C9*100/D9 -> #DIV/0!
E10: =C10*100/D10 -> #DIV/0!
E11: =C11*100/D11 -> #DIV/0!
E12: =C12*100/D12 -> #DIV/0!
E13: =C13*100/D13 -> #DIV/0!
E14: =C14*100/D14 -> #DIV/0!
E15: =C15*100/D15 -> #DIV/0!
E16: =C16*100/D16 -> #DIV/0!
E17: =C17*100/D17 -> #DIV/0!
E18: =C18*100/D18 -> #DIV/0!
... E452: =C452*100/D452 -> #DIV/0!

Sheet Acomp
G1: Acompanhamento Antropométrico
A3: Paciente | J3: Paciente
B4: DATA | C4: DATA | D4: DATA | E4: DATA | F4: DATA | G4: DATA | K4: DATA | L4: DATA | M4: DATA | N4: DATA | O4: DATA | P4: DATA
A5: CB | J5: CB
A6: CP | J6: CP
A7: Peso | J7: Peso
A8: DCT | J8: DCT
A9: AJ | J9: AJ
A13: Paciente | J13: Paciente
B14: DATA | C14: DATA | D14: DATA | E14: DATA | F14: DATA | G14: DATA | K14: DATA | L14: DATA | M14: DATA | N14: DATA | O14: DATA | P14: DATA
A15: CB | J15: CB
A16: CP | J16: CP
A17: Peso | J17: Peso
A18: DCT | J18: DCT
A19: AJ | J19: AJ
A21: Paciente | J21: Paciente
B22: DATA | C22: DATA | D22: DATA | E22: DATA | F22: DATA | G22: DATA | K22: DATA | L22: DATA | M22: DATA | N22: DATA | O22: DATA | P22: DATA
A23: CB | J23: CB
A24: CP | J24: CP
A25: Peso | J25: Peso
A26: DCT | J26: DCT
A27: AJ | J27: AJ
A29: Paciente | J29: Paciente
B30: DATA | C30: DATA | D30: DATA | E30: DATA | F30: DATA | G30: DATA | K30: DATA | L30: DATA | M30: DATA | N30: DATA | O30: DATA | P30: DATA
A31: CB | J31: CB
A32: CP | J32: CP
A33: Peso | J33: Peso
A34: DCT | J34: DCT
A35: AJ | J35: AJ

Sheet Paciente
D1: SEGUNDA | G1: TERÇA | J1: QUARTA | M1: QUINTA | P1: SEXTA
A2: Paciente | D2: Dieta | G2: Dieta | J2: Dieta | M2: Dieta | P2: Dieta
A3: Codigo | D3: HGT's: | G3: HGT's: | J3: HGT's: | M3: HGT's: | P3: HGT's:
A4: Idade | D4: VM/ O2/ AA | G4: VM/ O2/ AA | J4: VM/ O2/ AA | M4: VM/ O2/ AA | P4: VM/ O2/ AA
A5: Data Int | D5: P: | G5: P: | J5: P: | M5: P: | P5: P:
A6: UTI | D6: Mg | G6: Mg | J6: Mg | M6: Mg | P6: Mg
A7: Peso | D7: K | G7: K | J7: K | M7: K | P7: K
A8: Peso ideal | D8: Na | G8: Na | J8: Na | M8: Na | P8: Na
A9: Altura | D9: Lact | G9: Lact | J9: Lact | M9: Lact | P9: Lact
A10: IMC | D10: PCR | G10: PCR | J10: PCR | M10: PCR | P10: PCR
A11: CB | D11: pH | G11: pH | J11: pH | M11: pH | P11: pH
A12: CP | D12: pCO2 | G12: pCO2 | J12: pCO2 | M12: pCO2 | P12: pCO2
A13: AJ | D13: HCO3 | G13: HCO3 | J13: HCO3 | M13: HCO3 | P13: HCO3
... A15: NP | D15: Diurese | G15: Diurese | J15: Diurese | M15: Diurese | P15: Diurese
D16: Evacuação | G16: Evacuação | J16: Evacuação | M16: Evacuação | P16: Evacuação
D17: % recebido NE | G17: % recebido NE | J17: % recebido NE | M17: % recebido NE | P17: % recebido NE
D20: SEGUNDA | G20: TERÇA | J20: QUARTA | M20: QUINTA | P20: SEXTA
A21: Paciente | D21: Dieta | G21: Dieta | J21: Dieta | M21: Dieta | P21: Dieta
A22: Codigo | D22: HGT's: | G22: HGT's: | J22: HGT's: | M22: HGT's: | P22: HGT's:
A23: Idade | D23: VM/ O2/ AA | G23: VM/ O2/ AA | J23: VM/ O2/ AA | M23: VM/ O2/ AA | P23: VM/ O2/ AA
A24: Data Int | D24: P: | G24: P: | J24: P: | M24: P: | P24: P:
A25: UTI | D25: Mg | G25: Mg | J25: Mg | M25: Mg | P25: Mg
A26: Peso | D26: K | G26: K | J26: K | M26: K | P26: K
A27: Peso ideal | D27: Na | G27: Na | J27: Na | M27: Na | P27: Na
A28: Altura | D28: Lact | G28: Lact | J28: Lact | M28: Lact | P28: Lact
A29: IMC | D29: PCR | G29: PCR | J29: PCR | M29: PCR | P29: PCR
A30: CB | D30: pH | G30: pH | J30: pH | M30: pH | P30: pH
A31: CP | D31: pCO2 | G31: pCO2 | J31: pCO2 | M31: pCO2 | P31: pCO2
A32: AJ | D32: HCO3 | G32: HCO3 | J32: HCO3 | M32: HCO3 | P32: HCO3
... A34: NP | D34: Diurese | G34: Diurese | J34: Diurese | M34: Diurese | P34: Diurese
D35: Evacuação | G35: Evacuação | J35: Evacuação | M35: Evacuação | P35: Evacuação
D36: % recebido NE | G36: % recebido NE | J36: % recebido NE | M36: % recebido NE | P36: % recebido NE
D39: SEGUNDA | G39: TERÇA | J39: QUARTA | M39: QUINTA | P39: SEXTA
A40: Paciente | D40: Dieta | G40: Dieta | J40: Dieta | M40: Dieta | P40: Dieta
A41: Codigo | D41: HGT's: | G41: HGT's: | J41: HGT's: | M41: HGT's: | P41: HGT's:
A42: Idade | D42: VM/ O2/ AA | G42: VM/ O2/ AA | J42: VM/ O2/ AA | M42: VM/ O2/ AA | P42: VM/ O2/ AA
A43: Data Int | D43: P: | G43: P: | J43: P: | M43: P: | P43: P:
A44: UTI | D44: Mg | G44: Mg | J44: Mg | M44: Mg | P44: Mg
A45: Peso | D45: K | G45: K | J45: K | M45: K | P45: K
A46: Peso ideal | D46: Na | G46: Na | J46: Na | M46: Na | P46: Na
...

Sheet Siglário
A1: AA | B1: Ar ambiente | C1: LIP | D1: Lipídeos
A2: AÇ | B2: açúcar | C2: Mg | D2: Magnésio
A3: AJ | B3: Altura do joelho | C3: Na | D3: Sódio
A4: BH | B4: Balanço hídrico | C4: NC | D4: Necessidades calóricas
A5: CA | B5: circunferência abdominal | C5: NC | D5: Necessidades calóricas
A6: CB | B6: circunferencia do braco | C6: NE | D6: Nutrição enteral
A7: CC | B7: circunferência da coxa | C7: NP | D7: Necessidades proteicas
A8: CHO | B8: carboidratos | C8: NP | D8: Necessidades proteicas
A9: Cont | B9: Contínua | C9: O2 | D9: Oxigênio
A10: CP | B10: circunferencia da panturrilha | C10: Osmol. | D10: Osmolaridades
A11: Desn | B11: Desnutrição | C11: P | D11: Fósforo
A12: HD | B12: Hemodiálise | C12: P50 | D12: Percenntil 50
... A17: Kcal | B17: Calorias | C17: Vol | D17: volume
A18: Lact | B18: Lactato
